Workbook

Sheet Notas
A1: PERSONAL CAPACITY FACTS — Notas de uso
A3: Propósito | B3: Insumo manual/semi-automático para el Personal Capacity Facts Gate (RE-032.3/RE-032.5) del SOP Research Engine. No sustituye al gate — alimenta el futuro adaptador que traduzca estas cifras a LocalPersonalCapacityFactsInputs.
A5: Código de color
A6: Azul | B6: Valor manual — actualizar cuando cambie la situación real
A7: Negro | B7: Fórmula derivada — no editar directamente
A9: Concepto: colchón vs. pólvora seca (suelo/techo)
A10: • | B10: Colchón: mínimo intocable, cubre necesidades básicas. Nunca se despliega.
A11: • | B11: Pólvora seca — techo: por encima, hay efectivo ocioso que debería estar invertido (coste de oportunidad).
A12: • | B12: Pólvora seca — suelo: munición mínima para aprovechar una oportunidad (ej. una caída de mercado) con el Dry Powder Protocol (RE-041.1). Por debajo, no hay peligro (el colchón sigue intacto) pero sí capacidad reducida de actuar cuando toca.
A14: Cadencia de actualización | B14: Actualizar cuando cambien ingresos, gastos, umbrales, deudas o vencimientos. Además, el último día de cada mes se realiza un cierre de estado: solo se registra si la fuente de cartera está actualizada; si no, queda pendiente.
A16: Fecha de valoración de origen | B16: Fechas de valoración vigentes: AMS actualizado desde su fichero de cartera a 2026-10-24; AML conserva su última actualización registrada a 2026-10-05.
A18: Abiertos / pendientes de decisión
A19: • | B19: AMS: techo de liquidez total fijado en 150.000€ (redondeo de 30.000 colchón + 125.000 pólvora óptima = 155.000€ exacto). Se asume pólvora óptima techo = 120.000€ para cuadrar el redondeo — confirmar si se prefiere mantener colchón exacto en 30.000€ o ajustar de otro modo.
A20: • | B20: AMS: concentración de ingresos valorada como adecuada y confirmada el 2026-10-25 (40% alquileres, 40% dividendos ETF y 20% otros).
A21: • | B21: AML: Fondo Monetario aún no operativo — se nutrirá de los depósitos a plazo al vencer (Pibank 26.08.26, Myinvestor 29.09.26). Actualizar esta hoja cuando eso ocurra.
A22: • | B22: AML: pólvora seca actual (74.375€) está por debajo del suelo objetivo (125.000€) — déficit de 50.625€ a recargar. Confirmado por Armando el 2026-08-10, sin plan de recarga definido aún.
A23: • | B23: Ambos: 'obligaciones fijas manejables' se deriva directamente de gasto anual vs. ingresos recurrentes — no es un input independiente.
A24: • | B24: Ambos: servicio de deuda fijado en 'manejable' de forma permanente — sin deuda, sin previsión. Revisar solo si esto cambia.
A25: • | B25: AMS: prevista una compra adicional de S&P 500 durante la semana del 2026-10-26 mediante traspaso desde el Fondo Monetario. No contabilizar hasta que la operación aparezca ejecutada en el fichero de cartera; entonces bajará FM y subirá S&P por el mismo importe, sin alterar el patrimonio total.
A26: • | B26: Proyecciones: nueva fecha de ancla 31/12/2026. Ese cierre fijará los saldos congelados; el seguimiento comparativo mensual empieza el 31/01/2027.

Sheet AMS
A1: PERSONAL CAPACITY FACTS — AMS (patrimonio propio)
A3: 1. LIQUIDEZ Y PÓLVORA SECA
A4: Concepto | B4: Valor | C4: Fuente | D4: Nota
A5: Gasto anual estimado | B5: 22000 | C5: Manual | D5: Estimación Armando
A6: Ingresos recurrentes anuales | B6: =B32 -> 15000 | C6: Fórmula (vinculado a Bloque 3) | D6: Vinculado a Bloque 3 (fila 32) = Alquileres + Dividendos ETF (JGPI) + Otros. Antes era un valor manual duplicado; ahora un único punto de verdad -- cambiar el desglose en Bloque 3 actualiza esto automáticamente.
A7: Gap anual (déficit) | B7: =B6-B5 -> -7000 | C7: Fórmula | D7: Negativo = déficit que la cartera debe poder cubrir
A8: Objetivo declarado | B8: Cerrar el gap con ingresos pasivos recurrentes | C8: Manual | D8: Confirmado 2026-08-10 -- históricamente cubierto de sobra con ingresos de consultoría (variables, no 'ciertos y conocidos', por eso excluidos de 'Ingresos recurrentes anuales'), pero el objetivo es cerrar los 7.000€/año con fuentes pasivas predecibles, no seguir dependiendo de la consultoría. Contexto, no una de las nueve categorías del gate.
A9: Colchón de seguridad mínimo (intocable) | B9: 30000 | C9: Manual | D9: ~4 años del gap anual (7.000€/año)
A10: Pólvora seca óptima — suelo | B10: 70000 | C10: Manual | D10: Fijado por coherencia con el modelo de dos capas de AML
A11: Pólvora seca óptima — techo | B11: 120000 | C11: Manual | D11: Ajustado para cuadrar el techo total redondeado en 150.000€ (ver nota arriba)
A12: Suelo de liquidez total (mínimo óptimo) | B12: =B9+B10 -> 100000 | C12: Fórmula
A13: Techo de liquidez total (máximo óptimo) | B13: =B9+B11 -> 150000 | C13: Fórmula
A14: Liquidez actual — cuenta | B14: 107200 | C14: Automático (cartera AMS, hoja '01. Resumen') | D14: VALOR LIQUIDEZ
A15: Liquidez actual — Fondo Monetario | B15: 84690 | C15: Automático (cartera AMS, hoja '01. Resumen') | D15: VALOR FM
A16: Liquidez total actual | B16: =SUM(B14:B15) -> 191890 | C16: Fórmula
A17: Pólvora seca actual | B17: =B16-B9 -> 161890 | C17: Fórmula
A18: Exceso/(Déficit) vs. suelo de liquidez | B18: =B16-B12 -> 91890 | C18: Fórmula
A19: Exceso/(Déficit) vs. techo de liquidez | B19: =B16-B13 -> 41890 | C19: Fórmula | D19: Positivo = liquidez ociosa por encima del objetivo
A20: Exceso/(Déficit) vs. pólvora óptima (suelo) | B20: =B17-B10 -> 91890 | C20: Fórmula
A21: Exceso/(Déficit) vs. pólvora óptima (techo) | B21: =B17-B11 -> 41890 | C21: Fórmula
A23: 2. DEUDA
A24: Concepto | B24: Valor | C24: Fuente | D24: Nota
A25: Servicio de deuda manejable | B25: Sí (fijo) | C25: Manual / fijo | D25: Sin deuda, sin previsión de contraerla
A27: 3. CONCENTRACIÓN DE INGRESOS
A28: Concepto | B28: Valor | C28: Fuente | D28: Nota
A29: Alquileres | B29: 6000 | C29: Manual
A30: Dividendos ETF (JGPI) | B30: 6000 | C30: Manual
A31: Otros | B31: 3000 | C31: Manual
A32: Total ingresos recurrentes | B32: =SUM(B29:B31) -> 15000 | C32: Fórmula
A33: % Alquileres | B33: =B29/B32 -> 0.4 | C33: Fórmula
A34: % Dividendos ETF | B34: =B30/B32 -> 0.4 | C34: Fórmula
A35: % Otros | B35: =B31/B32 -> 0.2 | C35: Fórmula
A36: Valoración cualitativa (concentración de ingresos) | B36: Adecuado | C36: Manual | D36: Confirmado 2026-10-25 — alquileres 40%, dividendos ETF 40% y otros 20%; ninguna fuente domina. El objetivo sigue siendo cerrar el déficit anual con ingresos pasivos recurrentes.
A38: 4. CONCENTRACIÓN DE CARTERA
A39: Concepto | B39: Valor | C39: Fuente | D39: Nota
A40: SP500 (fondos indexados) | B40: 891003 | C40: Automático (cartera AMS, hoja '01. Resumen')
A41: Fondo Monetario | B41: =B15 -> 84690 | C41: Automático (cartera AMS, hoja '01. Resumen')
A42: ETF | B42: 90795 | C42: Automático (cartera AMS, hoja '01. Resumen')
A43: Pisos | B43: 100000 | C43: Automático (cartera AMS, hoja '01. Resumen')
A44: Liquidez (excluido FM) | B44: =B14 -> 107200 | C44: Automático (cartera AMS, hoja '01. Resumen') | D44: No confundir con 'Liquidez total actual' de la sección 1, que sí incluye el Fondo Monetario; aquí el FM figura aparte como clase de activo propia.
...

Sheet AML
A1: PERSONAL CAPACITY FACTS — AML (patrimonio de tus padres)
A3: 1. LIQUIDEZ Y PÓLVORA SECA
A4: Concepto | B4: Valor | C4: Fuente | D4: Nota
A5: Gasto anual estimado | B5: 32500 | C5: Manual | D5: Rango 30.000-35.000€, punto medio usado
A6: Ingresos recurrentes anuales | B6: =B32 -> 80000 | C6: Fórmula (vinculado a Bloque 3) | D6: Vinculado a Bloque 3 (fila 32) = Pensiones públicas + Dividendos. Antes era un valor manual duplicado; ahora un único punto de verdad -- cambiar el desglose en Bloque 3 actualiza esto automáticamente.
A7: Superávit anual | B7: =B6-B5 -> 47500 | C7: Fórmula | D7: Positivo = no necesitan tocar la cartera para vivir
A8: Colchón de seguridad mínimo (intocable) | B8: 125000 | C8: Manual | D8: Nunca por debajo de esta cifra
A9: Pólvora seca óptima — suelo | B9: 125000 | C9: Manual
A10: Pólvora seca óptima — techo | B10: 175000 | C10: Manual
A11: Suelo de liquidez total (mínimo óptimo) | B11: =B8+B9 -> 250000 | C11: Fórmula
A12: Techo de liquidez total (máximo óptimo) | B12: =B8+B10 -> 300000 | C12: Fórmula | D12: Confirmado: 125.000+175.000=300.000€, cuadra con la cifra original
A13: Liquidez actual — cuenta | B13: 54375 | C13: Automático (cartera AML, hoja '01a. Resumen AML')
A14: Liquidez actual — Depósito Myinvestor (3,1% TAE) | B14: 60000 | C14: Automático (cartera AML, hoja '01a. Resumen AML') | D14: Vence 05.10.27
A15: Liquidez actual — Depósito Pibank (2% TAE) | B15: 0 | C15: Automático (cartera AML, hoja '01a. Resumen AML') | D15: Depósito liberado 2026-08-26 -- reinvertido en Fondo Monetario (ver fila 16). Importe histórico: 85.000€
A16: Liquidez actual — Fondo Monetario | B16: 95172 | C16: Manual | D16: Nutrido 2026-08-26 con el depósito Pibank liberado (85.000€)
A17: Liquidez total actual | B17: =SUM(B13:B16) -> 209547 | C17: Fórmula
A18: Pólvora seca actual | B18: =B17-B8 -> 84547 | C18: Fórmula
A19: Exceso/(Déficit) vs. suelo de liquidez | B19: =B17-B11 -> -40453 | C19: Fórmula
A20: Exceso/(Déficit) vs. techo de liquidez | B20: =B17-B12 -> -90453 | C20: Fórmula
A21: Exceso/(Déficit) vs. pólvora óptima (suelo) | B21: =B18-B9 -> -40453 | C21: Fórmula | D21: Negativo = hoy tienen menos pólvora seca que el objetivo mínimo — recargar hasta cubrir este déficit
A22: Exceso/(Déficit) vs. pólvora óptima (techo) | B22: =B18-B10 -> -90453 | C22: Fórmula
A24: 2. DEUDA
A25: Concepto | B25: Valor | C25: Fuente | D25: Nota
A26: Servicio de deuda manejable | B26: Sí (fijo) | C26: Manual / fijo | D26: Sin deuda, sin previsión de contraerla
A28: 3. CONCENTRACIÓN DE INGRESOS
A29: Concepto | B29: Valor | C29: Fuente | D29: Nota
A30: Pensiones públicas (netas) | B30: 60000 | C30: Manual | D30: 30.000€ neto c/u
A31: Dividendos (netos) | B31: 20000 | C31: Manual
A32: Total ingresos recurrentes | B32: =SUM(B30:B31) -> 80000 | C32: Fórmula
A33: % Pensiones | B33: =B30/B32 -> 0.75 | C33: Fórmula
A34: % Dividendos | B34: =B31/B32 -> 0.25 | C34: Fórmula
A35: Valoración cualitativa (concentración de ingresos) | B35: Adecuado | C35: Manual | D35: Fuente dominante (pensión pública) es la más estable posible; ingreso total muy por encima del gasto
A37: 4. CONCENTRACIÓN DE CARTERA
A38: Concepto | B38: Valor | C38: Fuente | D38: Nota
A39: Fondos RV | B39: 2227928 | C39: Automático (cartera AML, hoja '01a. Resumen AML')
A40: Planes de Pensiones (Papá + Mamá) | B40: =B60+B61 -> 1171556 | C40: Automático (cartera AML, hoja '01a. Resumen AML') | D40: Excluidos de liquidez/pólvora seca — ver sección 6
A41: Acciones (Iberdrola + BBVA + TEF) | B41: =SUM(B52:B54) -> 533898 | C41: Automático (cartera AML, hoja '01a. Resumen AML')
A42: ETF (Aristócratas) | B42: 130983 | C42: Automático (cartera AML, hoja '01a. Resumen AML')
A43: Liquidez + Depósitos + FM | B43: =B17 -> 209547 | C43: Fórmula (vinculado a Bloque 1, fila 17) | D43: Vinculado a Liquidez total actual (Bloque 1, fila 17) = cuenta + depósitos + Fondo Monetario. Antes era un valor manual fijo que excluía el FM y solo cuadraba por coincidencia mientras el FM estaba a 0€; ahora que el FM tiene 85.000€, el vínculo evita perder ese importe del Total patrimonio.
A44: Total patrimonio | B44: =SUM(B39:B43) -> 4273912 | C44: Fórmula
...

Sheet Cajas
A1: CLASIFICACIÓN EN LAS TRES CAJAS
A2: Nivel 3, CONSTITUTION.md Sección 2 · Seguridad · Motor · Rentas Pasivas
A4: AMS — patrimonio propio
A5: Caja | B5: Partida | C5: Valor | D5: % Total | E5: Origen | F5: Nota
A6: Seguridad | B6: =AMS!A41 -> Fondo Monetario | C6: =AMS!B41 -> 84690 | E6: AMS!B41
B7: =AMS!A44 -> Liquidez (excluido FM) | C7: =AMS!B44 -> 107200 | E7: AMS!B44
B8: Subtotal Seguridad | C8: =SUM(C6:C7) -> 191890 | D8: =C8/C$15 -> 0.15065699
A9: Motor | B9: =AMS!A40 -> SP500 (fondos indexados) | C9: =AMS!B40 -> 891003 | E9: AMS!B40
B10: Subtotal Motor | C10: =C9 -> 891003 | D10: =C10/C$15 -> 0.69954573
A11: Rentas Pasivas | B11: =AMS!A42 -> ETF | C11: =AMS!B42 -> 90795 | E11: AMS!B42
B12: =AMS!A43 -> Pisos | C12: =AMS!B43 -> 100000 | E12: AMS!B43
B13: Subtotal Rentas Pasivas | C13: =SUM(C11:C12) -> 190795 | D13: =C13/C$15 -> 0.14979728
A15: TOTAL AMS (3 cajas) | C15: =C8+C10+C13 -> 1273688 | D15: =C15/C15 -> 1
B16: Diferencia vs. total patrimonio (control) | C16: =C15-AMS!B45 -> 0 | F16: Debe ser 0€. Si no lo es, hay una partida nueva en la sección 4 sin clasificar aquí.
A19: AML — patrimonio de tus padres
A20: Caja | B20: Partida | C20: Valor | D20: % Total | E20: Origen | F20: Nota
A21: Seguridad | B21: =AML!A43 -> Liquidez + Depósitos + FM | C21: =AML!B43 -> 209547 | E21: AML!B43
B22: Subtotal Seguridad | C22: =C21 -> 209547 | D22: =C22/C$30 -> 0.04902932
A23: Motor | B23: =AML!A39 -> Fondos RV | C23: =AML!B39 -> 2227928 | E23: AML!B39
B24: =AML!A40 -> Planes de Pensiones (Papá + Mamá) | C24: =AML!B40 -> 1171556 | E24: AML!B40 | F24: Bloqueado operativamente (ilíquido salvo jubilación/paro larga duración/enfermedad grave; destino: herencia). Clasificado en Motor por composición de activo, confirmado por Armando 2026-08-13.
B25: Subtotal Motor | C25: =SUM(C23:C24) -> 3399484 | D25: =C25/C$30 -> 0.79540337
A26: Rentas Pasivas | B26: =AML!A41 -> Acciones (Iberdrola + BBVA + TEF) | C26: =AML!B41 -> 533898 | E26: AML!B41 | F26: Función declarada de renta vía dividendos, no de crecimiento (ver AML!D58). Confirmado por Armando 2026-08-13.
B27: =AML!A42 -> ETF (Aristócratas) | C27: =AML!B42 -> 130983 | E27: AML!B42
B28: Subtotal Rentas Pasivas | C28: =SUM(C26:C27) -> 664881 | D28: =C28/C$30 -> 0.15556731
A30: TOTAL AML (3 cajas) | C30: =C22+C25+C28 -> 4273912 | D30: =C30/C30 -> 1
B31: Diferencia vs. total patrimonio (control) | C31: =C30-AML!B44 -> 0 | F31: Debe ser 0€. Si no lo es, hay una partida nueva en la sección 4 sin clasificar aquí.
A33: Colores: Seguridad (azul) · Motor (verde) · Rentas Pasivas (naranja). % Total = peso de cada caja sobre el patrimonio total de AMS o AML respectivamente. Clasificación fijada por Armando el 2026-08-13 sobre la tabla de cajas de CONSTITUTION.md Sección 2, Nivel 3 — Seguridad: liquidez/depósitos/monetarios · Motor: fondo indexado S&P 500 y otras inversiones a largo plazo · Rentas Pasivas: JGPI, inmobiliario, oro.

Sheet Proyecciones
A1: PROYECCIÓN CAJA MOTOR — HIPÓTESIS BASE v1
A2: Ilustrativa, no un objetivo. X/Y/Z por necesidad patrimonial: CONSTITUTION.md Sección 6, Pendiente. Nueva ancla de trayectoria: cierre de 31/12/2026. El seguimiento activo empieza en enero de 2027 y se registra el último día de cada mes.
A4: Hipótesis de rentabilidad · CONSTITUTION.md Sección 2
A5: Concepto | B5: Valor | C5: Fuente | D5: Nota
A6: Rentabilidad real anualizada | B6: 0.07 | C6: Manual | D6: Hipótesis base v1 — CONSTITUTION.md Sección 2. Serie total return real de Shiller (data/raw/shiller.xlsx), dividendos reinvertidos, CAGR de la serie completa. No se ajusta automáticamente por CAPE ni por el Research Engine — editar solo tras actualización explícita de la Constitución.
A7: Rentabilidad nominal anualizada (aprox.) | B7: 0.094 | C7: Manual | D7: Derivada de la rentabilidad real + inflación media histórica de la serie Shiller (~2,15%/año). Misma gobernanza que la fila anterior. Compartida por los dos bloques (AMS y AML) — misma hipótesis de mercado.
A9: BLOQUE AMS — Caja Motor (patrimonio propio)
A10: Fecha y saldo de referencia · congelado, no enlazado por fórmula
A11: Concepto | B11: Valor | C11: Fuente | D11: Nota
A12: Fecha de referencia | B12: 46387 | C12: Manual / cierre mensual | D12: Ancla definitiva de año natural. El saldo se congelará en el cierre del 31/12/2026; hasta entonces la trayectoria nueva no está activa.
A13: AMS — Caja Motor (congelado) | C13: Pendiente de cierre 31/12/2026 | D13: Se tomará de AMS!B40 una vez actualizado el fichero de cartera al cierre. Debe quedar como valor congelado, no como enlace vivo.
A15: Trayectoria esperada desde el congelado
A16: Horizonte | B16: Fecha objetivo | C16: Real | D16: Nominal
A17: 5 años | B17: =IF(OR($B$12="",$B$13=""),"",DATE(YEAR($B$12)+5,MONTH($B$12),DAY($B$12))) | C17: =IF($B$13="","",$B$13*(1+$B$6)^5) | D17: =IF($B$13="","",$B$13*(1+$B$7)^5)
A18: 10 años | B18: =IF(OR($B$12="",$B$13=""),"",DATE(YEAR($B$12)+10,MONTH($B$12),DAY($B$12))) | C18: =IF($B$13="","",$B$13*(1+$B$6)^10) | D18: =IF($B$13="","",$B$13*(1+$B$7)^10)
A19: 15 años | B19: =IF(OR($B$12="",$B$13=""),"",DATE(YEAR($B$12)+15,MONTH($B$12),DAY($B$12))) | C19: =IF($B$13="","",$B$13*(1+$B$6)^15) | D19: =IF($B$13="","",$B$13*(1+$B$7)^15)
A21: Seguimiento — saldo real vs. trayectoria esperada (nominal)
A22: Fecha de control | B22: Años | C22: Actual | D22: Esperado | E22: Δ
A23: 46418 | B23: =IF(OR($A23="",$B$12=""),"",($A23-$B$12)/365.25) -> 0.084873374 | D23: =IF(OR($A23="",$B$13=""),"",$B$13*(1+$B$7)^$B23) | E23: =IF(OR($A23="",$C23="",$D23=""),"",$C23-$D23)
A24: 46446 | B24: =IF(OR($A24="",$B$12=""),"",($A24-$B$12)/365.25) -> 0.1615332 | D24: =IF(OR($A24="",$B$13=""),"",$B$13*(1+$B$7)^$B24) | E24: =IF(OR($A24="",$C24="",$D24=""),"",$C24-$D24)
A25: 46477 | B25: =IF(OR($A25="",$B$12=""),"",($A25-$B$12)/365.25) -> 0.24640657 | D25: =IF(OR($A25="",$B$13=""),"",$B$13*(1+$B$7)^$B25) | E25: =IF(OR($A25="",$C25="",$D25=""),"",$C25-$D25)
A26: 46507 | B26: =IF(OR($A26="",$B$12=""),"",($A26-$B$12)/365.25) -> 0.32854209 | D26: =IF(OR($A26="",$B$13=""),"",$B$13*(1+$B$7)^$B26) | E26: =IF(OR($A26="",$C26="",$D26=""),"",$C26-$D26)
A27: 46538 | B27: =IF(OR($A27="",$B$12=""),"",($A27-$B$12)/365.25) -> 0.41341547 | D27: =IF(OR($A27="",$B$13=""),"",$B$13*(1+$B$7)^$B27) | E27: =IF(OR($A27="",$C27="",$D27=""),"",$C27-$D27)
A28: 46568 | B28: =IF(OR($A28="",$B$12=""),"",($A28-$B$12)/365.25) -> 0.49555099 | D28: =IF(OR($A28="",$B$13=""),"",$B$13*(1+$B$7)^$B28) | E28: =IF(OR($A28="",$C28="",$D28=""),"",$C28-$D28)
A40: BLOQUE AML — Caja Motor (patrimonio de tus padres)
A41: Fecha y saldo de referencia · congelado, no enlazado por fórmula
A42: Concepto | B42: Valor | C42: Fuente | D42: Nota
A43: Fecha de referencia | B43: 46387 | C43: Manual / cierre mensual | D43: Misma fecha de ancla que AMS. Los saldos AML se congelarán únicamente tras recibir y validar su fichero actualizado al cierre.
A44: AML — Fondos RV (congelado) | C44: Pendiente de cierre 31/12/2026 | D44: Se tomará de AML!B39 y quedará congelado.
A45: AML — Planes de Pensiones (congelado) | C45: Pendiente de cierre 31/12/2026 | D45: Se tomará de AML!B40 y quedará congelado.
A46: AML — Caja Motor (congelado, total) | B46: =IF(COUNT(B44:B45)<2,"",SUM(B44:B45)) | C46: Fórmula | D46: Suma de las dos filas anteriores. Sigue siendo un congelado: solo se mueve si cambian esas dos celdas manualmente.
A48: Trayectoria esperada desde el congelado
A49: Horizonte | B49: Fecha objetivo | C49: Real | D49: Nominal
A50: 5 años | B50: =IF(OR($B$43="",$B$46=""),"",DATE(YEAR($B$43)+5,MONTH($B$43),DAY($B$43))) | C50: =IF($B$46="","",$B$46*(1+$B$6)^5) | D50: =IF($B$46="","",$B$46*(1+$B$7)^5)
A51: 10 años | B51: =IF(OR($B$43="",$B$46=""),"",DATE(YEAR($B$43)+10,MONTH($B$43),DAY($B$43))) | C51: =IF($B$46="","",$B$46*(1+$B$6)^10) | D51: =IF($B$46="","",$B$46*(1+$B$7)^10)
A52: 15 años | B52: =IF(OR($B$43="",$B$46=""),"",DATE(YEAR($B$43)+15,MONTH($B$43),DAY($B$43))) | C52: =IF($B$46="","",$B$46*(1+$B$6)^15) | D52: =IF($B$46="","",$B$46*(1+$B$7)^15)
A54: Seguimiento — saldo real vs. trayectoria esperada (nominal)
A55: Fecha de control | B55: Años | C55: Actual | D55: Esperado | E55: Δ
A56: 46418 | B56: =IF(OR($A56="",$B$43=""),"",($A56-$B$43)/365.25) -> 0.084873374 | D56: =IF(OR($A56="",$B$46=""),"",$B$46*(1+$B$7)^$B56) | E56: =IF(OR($A56="",$C56="",$D56=""),"",$C56-$D56)
A57: 46446 | B57: =IF(OR($A57="",$B$43=""),"",($A57-$B$43)/365.25) -> 0.1615332 | D57: =IF(OR($A57="",$B$46=""),"",$B$46*(1+$B$7)^$B57) | E57: =IF(OR($A57="",$C57="",$D57=""),"",$C57-$D57)
...
